<?xml version="1.0" ?>
<sdf version="1.8">
    <world name="neobot_world">
        <physics name="1ms" type="ignored">
            <max_step_size>0.001</max_step_size>
            <real_time_factor>1.0</real_time_factor>
        </physics>
        <plugin
            filename="gz-sim-physics-system"
            name="gz::sim::systems::Physics">
        </plugin>
        <plugin
            filename="gz-sim-user-commands-system"
            name="gz::sim::systems::UserCommands">
        </plugin>
        <plugin
            filename="gz-sim-scene-broadcaster-system"
            name="gz::sim::systems::SceneBroadcaster">
        </plugin>
        <plugin filename="gz-sim-imu-system"
                name="gz::sim::systems::Imu">
        </plugin>
        <plugin filename="gz-sim-sensors-system"
                name="gz::sim::systems::Sensors">
            <render_engine>ogre2</render_engine>
        </plugin>
        <plugin filename="gz-sim-joint-state-publisher-system"
                name="gz::sim::systems::JointStatePublisher">
        </plugin>

        <!-- <gui fullscreen="0">

            
            <plugin filename="MinimalScene" name="3D View">
                <gz-gui>
                  <title>3D View</title>
                  <property type="bool" key="showTitleBar">false</property>
                  <property type="string" key="state">docked</property>
                </gz-gui>
              
                <engine>ogre2</engine>
                <scene>scene</scene>
                <ambient_light>0.4 0.4 0.4</ambient_light>
                <background_color>0.8 0.8 0.8</background_color>
                <camera_pose>-6 0 6 0 0.5 0</camera_pose>
                <camera_clip>
                  <near>0.25</near>
                  <far>25000</far>
                </camera_clip>
              </plugin>
              <plugin filename="GzSceneManager" name="Scene Manager">
                <gz-gui>
                  <property key="resizable" type="bool">false</property>
                  <property key="width" type="double">5</property>
                  <property key="height" type="double">5</property>
                  <property key="state" type="string">floating</property>
                  <property key="showTitleBar" type="bool">false</property>
                </gz-gui>
              </plugin>

            
            <plugin filename="WorldControl" name="World control">
                <gz-gui>
                    <title>World control</title>
                    <property type="bool" key="showTitleBar">false</property>
                    <property type="bool" key="resizable">false</property>
                    <property type="double" key="height">72</property>
                    <property type="double" key="width">150</property>
                    <property type="double" key="z">1</property>

                    <property type="string" key="state">floating</property>
                    <anchors target="3D View">
                    <line own="left" target="left"/>
                    <line own="bottom" target="bottom"/>
                    </anchors>
                </gz-gui>

                <play_pause>true</play_pause>
                <step>true</step>
                <start_paused>true</start_paused>
                <service>/world/world_demo/control</service>
                <stats_topic>/world/world_demo/stats</stats_topic>
            </plugin>

            
            <plugin filename="WorldStats" name="World stats">
                <gz-gui>
                    <title>World stats</title>
                    <property type="bool" key="showTitleBar">false</property>
                    <property type="bool" key="resizable">false</property>
                    <property type="double" key="height">110</property>
                    <property type="double" key="width">290</property>
                    <property type="double" key="z">1</property>

                    <property type="string" key="state">floating</property>
                    <anchors target="3D View">
                    <line own="right" target="right"/>
                    <line own="bottom" target="bottom"/>
                    </anchors>
                </gz-gui>

                <sim_time>true</sim_time>
                <real_time>true</real_time>
                <real_time_factor>true</real_time_factor>
                <iterations>true</iterations>
                <topic>/world/world_demo/stats</topic>

            </plugin>

            <plugin filename="EntityTree" name="Entity tree">
            </plugin>

        </gui> -->

  


        <light type="directional" name="sun">
            <cast_shadows>true</cast_shadows>
            <pose>0 0 10 0 0 0</pose>
            <diffuse>0.8 0.8 0.8 1</diffuse>
            <specular>0.2 0.2 0.2 1</specular>
            <attenuation>
                <range>1000</range>
                <constant>0.9</constant>
                <linear>0.01</linear>
                <quadratic>0.001</quadratic>
            </attenuation>
            <direction>-0.5 0.1 -0.9</direction>
        </light>

        <model name="ground_plane">
            <static>true</static>
            <link name="link">
                <collision name="collision">
                <geometry>
                    <plane>
                    <normal>0 0 1</normal>
                    </plane>
                </geometry>
                </collision>
                <visual name="visual">
                <geometry>
                    <plane>
                    <normal>0 0 1</normal>
                    <size>100 100</size>
                    </plane>
                </geometry>
                <material>
                    <ambient>0.8 0.8 0.8 1</ambient>
                    <diffuse>0.8 0.8 0.8 1</diffuse>
                    <specular>0.8 0.8 0.8 1</specular>
                </material>
                </visual>
            </link>
        </model>

        <model name='neobot'>

            <!-- LINKS -->

            <link name="base_footprint">
                <!-- <pose>0 0 0 0 0 0</pose> -->
            </link>

            <link name='base_link'>
                <pose relative_to='base_footprint_joint'>0 0 0 0 0 0</pose>
                <inertial>
                    <pose>0.019736266638338499 -0.00103592208239938 0.024943774276299499 0 0 0</pose>
                    <mass>2.8860000000000001</mass>
                    <inertia>
                    <ixx>0.0230886</ixx>
                    <ixy>-0.00059632880</ixy>
                    <ixz>0.00089059654</ixz>
                    <iyy>0.040993868</iyy>
                    <iyz>-0.00001729413</iyz>
                    <izz>0.056762850</izz>
                    </inertia>
                </inertial>
                <collision name='base_link_collision_frame'>
                    <pose>0 0 0.037 0 0 0</pose>
                    <geometry>
                        <box>
                            <size>0.34 0.26 0.120</size>
                        </box>
                    </geometry>
                </collision>
                <collision name='base_link_collision_lidar'>
                    <pose>0.18 0 0.026 0 0 0</pose>
                    <geometry>
                        <cylinder>
                            <length>0.0526</length>
                            <radius>0.04</radius>
                        </cylinder>
                    </geometry>
                </collision>
                <collision name='base_link_collision_camera'>
                    <pose>0.184025 0 0.072 0 0 0</pose>
                    <geometry>
                        <box>
                            <size>0.02805 0.09 0.025</size>
                        </box>
                    </geometry>
                </collision>
                <visual name='base_link_visual'>
                    <pose>0 0 0 0 0 0</pose>
                    <geometry>
                    <mesh>
                        <scale>1 1 1</scale>
                        <uri>../meshes/base_link.STL</uri>
                    </mesh>
                    </geometry>
                    <material>
                    <diffuse>0.941176474 0.941176474 0.941176474 1</diffuse>
                    <ambient>0.941176474 0.941176474 0.941176474 1</ambient>
                    </material>
                </visual>

                <sensor name="imu_sensor" type="imu">
                    <always_on>1</always_on>
                    <update_rate>1</update_rate>
                    <visualize>true</visualize>
                    <topic>imu</topic>
                </sensor>

                <sensor name='gpu_lidar' type='gpu_lidar'>"
                    <pose relative_to='lidar_frame'>0 0 0 0 0 0</pose>
                    <topic>lidar</topic>
                    <update_rate>10</update_rate>
                    <ray>
                        <scan>
                            <horizontal>
                                <samples>180</samples>
                                <resolution>1</resolution>
                                <min_angle>-1.57</min_angle>
                                <max_angle>1.57</max_angle>
                            </horizontal>
                            <vertical>
                                <samples>1</samples>
                                <resolution>0.01</resolution>
                                <min_angle>0</min_angle>
                                <max_angle>0</max_angle>
                            </vertical>
                        </scan>
                        <range>
                            <min>0.08</min>
                            <max>8.0</max>
                            <resolution>0.01</resolution>
                        </range>
                    </ray>
                    <always_on>1</always_on>
                    <visualize>true</visualize>
                </sensor>

                <sensor name="realsense" type="depth_camera">
                    <pose relative_to='depth_camera_frame'>0 0 0 0 0 0</pose>
                    <update_rate>30.0</update_rate>
                    <topic>realsense</topic>
                    <camera>
                        <camera_info_topic>realsense/camera_info</camera_info_topic>
                        <horizontal_fov>1.20428</horizontal_fov>
                        <image>
                            <width>640</width>
                            <height>480</height>
                            <format>R8G8B8</format>
                        </image>
                        <clip>
                            <near>0.1</near>
                            <far>4.0</far>
                        </clip>
                    </camera>
                </sensor>

                <!-- <sensor name="rgb_camera" type="camera">
                    <pose relative_to='depth_camera_frame'>0 0 0 0 0 0</pose>
                    <update_rate>30.0</update_rate>
                    <topic>rgb_camera</topic>
                    <camera>
                        <camera_info_topic>rgb_camera/camera_info</camera_info_topic>
                        <horizontal_fov>1.20428</horizontal_fov>
                        <image>
                            <width>640</width>
                            <height>480</height>
                            <format>R8G8B8</format>
                        </image>
                        <clip>
                            <near>0.1</near>
                            <far>4.0</far>
                        </clip>
                    </camera>
                </sensor> -->


            </link>

            <link name='left_wheel_link'>
                <pose relative_to='left_wheel_joint'>0 0 0 0 0 0</pose>
                <inertial>
                    <pose>0 0.015369 0 0 0 0</pose>
                    <mass>0.132</mass>
                    <inertia>
                    <ixx>0.000103824895</ixx>
                    <ixy>0</ixy>
                    <ixz>0</ixz>
                    <iyy>0.000183869513</iyy>
                    <iyz>0</iyz>
                    <izz>0.000103824895</izz>
                    </inertia>
                </inertial>
                <collision name='left_wheel_link_collision'>
                    <pose>0 0.02 0 1.57079632679 0 0</pose>
                    <geometry>
                        <cylinder>
                            <length>0.04</length>
                            <radius>0.05</radius>
                        </cylinder>
                    </geometry>
                </collision>
                <visual name='left_wheel_link_visual'>
                    <pose>0 0 0 0 0 0</pose>
                    <geometry>
                    <mesh>
                        <scale>1 1 1</scale>
                        <uri>../meshes/left_wheel_link.STL</uri>
                    </mesh>
                    </geometry>
                    <material>
                    <diffuse>0.872550011 0.872550011 0.872550011 1</diffuse>
                    <ambient>0.872550011 0.872550011 0.872550011 1</ambient>
                    </material>
                </visual>
            </link>

            <link name='right_wheel_link'>
                <pose relative_to='right_wheel_joint'>0 0 0 0 0 0</pose>
                <inertial>
                    <pose>0 -0.015369 0 0 0 0</pose>
                    <mass>0.132</mass>
                    <inertia>
                    <ixx>0.000103824895</ixx>
                    <ixy>0</ixy>
                    <ixz>0</ixz>
                    <iyy>0.000183869513</iyy>
                    <iyz>0</iyz>
                    <izz>0.000103824895</izz>
                    </inertia>
                </inertial>
                <collision name='right_wheel_link_collision'>
                    <pose>0 -0.02 0 1.57079632679 0 0</pose>
                    <geometry>
                        <cylinder>
                            <length>0.04</length>
                            <radius>0.05</radius>
                        </cylinder>
                    </geometry>
                </collision>
                <visual name='right_wheel_link_visual'>
                    <pose>0 0 0 0 0 0</pose>
                    <geometry>
                    <mesh>
                        <scale>1 1 1</scale>
                        <uri>../meshes/right_wheel_link.STL</uri>
                    </mesh>
                    </geometry>
                    <material>
                    <diffuse>0.872550011 0.872550011 0.872550011 1</diffuse>
                    <ambient>0.872550011 0.872550011 0.872550011 1</ambient>
                    </material>
                </visual>
            </link>

            <link name='front_castor_link'>
                <pose relative_to='front_castor_frame'/>
                <inertial>
                    <pose>0 0 0 0 0 0</pose>
                    <mass>0.0138</mass>
                    <inertia>
                    <ixx>0.000000312122139</ixx>
                    <ixy>0</ixy>
                    <ixz>0</ixz>
                    <iyy>0.000000312122139</iyy>
                    <iyz>0</iyz>
                    <izz>0.000000312122139</izz>
                    </inertia>
                </inertial>
                <collision name='front_castor_link_collision'>
                    <pose>0 0 0 0 0 0</pose>
                    <geometry>
                    <sphere>
                        <radius>0.0075</radius>
                    </sphere>
                    </geometry>
                </collision>
                <visual name='front_castor_link_visual'>
                    <pose>0 0 0 0 0 0</pose>
                    <geometry>
                    <mesh>
                        <scale>1 1 1</scale>
                        <uri>../meshes/front_castor_link.STL</uri>
                    </mesh>
                    </geometry>
                    <material>
                    <diffuse>0.808824956 0.774512529 0.735300064 1</diffuse>
                    <ambient>0.808824956 0.774512529 0.735300064 1</ambient>
                    </material>
                </visual>
            </link>

            <link name='rear_castor_link'>
                <pose relative_to='rear_castor_frame'/>
                <inertial>
                    <pose>0 0 0 0 0 0</pose>
                    <mass>0.0138</mass>
                    <inertia>
                    <ixx>0.000000312122139</ixx>
                    <ixy>0</ixy>
                    <ixz>0</ixz>
                    <iyy>0.000000312122139</iyy>
                    <iyz>0</iyz>
                    <izz>0.000000312122139</izz>
                    </inertia>
                </inertial>
                <collision name='rear_castor_link_collision'>
                    <pose>0 0 0 0 0 0</pose>
                    <geometry>
                    <sphere>
                        <radius>0.0075</radius>
                    </sphere>
                    </geometry>
                </collision>
                <visual name='rear_castor_link_visual'>
                    <pose>0 0 0 0 0 0</pose>
                    <geometry>
                    <mesh>
                        <scale>1 1 1</scale>
                        <uri>../meshes/rear_castor_link.STL</uri>
                    </mesh>
                    </geometry>
                    <material>
                    <diffuse>0.808824956 0.774512529 0.735300064 1</diffuse>
                    <ambient>0.808824956 0.774512529 0.735300064 1</ambient>
                    </material>
                </visual>
            </link>

            <frame name="front_castor_frame" attached_to='base_link'>
                <pose>0.12 0 -0.026499999999999999 0 0 0</pose>
            </frame>

            <frame name="rear_castor_frame" attached_to='base_link'>
                <pose>-0.12 0 -0.026499999999999999 0 0 0</pose>
            </frame>

            <frame name="lidar_frame" attached_to='base_link'>
                <pose>0.18 0 0.0376 0 0 0</pose>
            </frame>

            <frame name="depth_camera_frame" attached_to='base_link'>
                <pose>0.18 0 1 0 0 0</pose>
            </frame>
            



            <!-- JOINTS -->

            <joint name='base_footprint_joint' type='fixed'>
                <pose relative_to='base_footprint'>0 0 0.0345 0 0 0</pose>
                    <parent>base_footprint</parent>
                    <child>base_link</child>
            </joint>

            <joint name='left_wheel_joint' type='revolute'>
                <pose relative_to='base_link'>0 0.13600000000000001 0.0155 0 0 0</pose>
                    <parent>base_link</parent>
                    <child>left_wheel_link</child>
                        <axis>
                            <xyz>0 1 0</xyz>
                            <limit>
                            <effort>1</effort>
                            <velocity>5</velocity>
                            <!-- <stiffness>100000000</stiffness> -->
                            <!-- <dissipation>1</dissipation> -->
                            <lower>-inf</lower>
                            <upper>inf</upper>
                            </limit>
                            <dynamics>
                            <spring_reference>0</spring_reference>
                            <spring_stiffness>0</spring_stiffness>
                            </dynamics>
                        </axis>
            </joint>


            <joint name='right_wheel_joint' type='revolute'>
                <pose relative_to='base_link'>0 -0.13600000000000001 0.0155 0 0 0</pose>
                    <parent>base_link</parent>
                    <child>right_wheel_link</child>
                        <axis>
                            <xyz>0 1 0</xyz>
                            <limit>
                            <effort>1</effort>
                            <velocity>5</velocity>
                            <!-- <stiffness>100000000</stiffness> -->
                            <!-- <dissipation>1</dissipation> -->
                            <lower>-inf</lower>
                            <upper>inf</upper>
                            </limit>
                            <dynamics>
                            <spring_reference>0</spring_reference>
                            <spring_stiffness>0</spring_stiffness>
                            </dynamics>
                        </axis>
            </joint>

            
            <joint name='front_castor_joint' type='ball'>
                    <parent>base_link</parent>
                    <child>front_castor_link</child>
            </joint>
            
            
            <joint name='rear_castor_joint' type='ball'>
                    <parent>base_link</parent>
                    <child>rear_castor_link</child>
            </joint>

            <plugin filename="gz-sim-diff-drive-system"
                name="gz::sim::systems::DiffDrive">
                <left_joint>left_wheel_joint</left_joint>
                <right_joint>right_wheel_joint</right_joint>
                <wheel_separation>0.272</wheel_separation>
                <wheel_radius>0.05</wheel_radius>
                <odom_publish_frequency>10</odom_publish_frequency>
                <max_velocity>2</max_velocity>
                <topic>cmd_vel</topic>
            </plugin>
            
        </model>

    </world>
</sdf>