<?xml version="1.0"?>
<robot xmlns:xacro="http://www.ros.org/wiki/xacro" name="neobot">

    <xacro:include filename="$(find neobot)/urdf/materials.xacro"/>


    <link name="base_footprint"/>

    <link name="base_link">
        <inertial>
            <origin xyz="0.0197362666383385 -0.00103592208239938 0.0249437742762995" rpy="0 0 0"/>
            <mass value="2.886"/>
            <inertia ixx="0.0230886"
                     ixy="-0.00059632880"
                     ixz="0.00089059654"
                     iyy="0.040993868"
                     iyz="-0.00001729413"
                     izz="0.056762850"/>
        </inertial>

        <collision name="base_link_collision_frame">
            <origin xyz="0 0 0.037" rpy="0 0 0"/>
            <geometry>
                <box size="0.34 0.26 0.12"/>
            </geometry>
        </collision>

        <collision name="base_link_collision_lidar">
            <origin xyz="0.18 0 0.026" rpy="0 0 0"/>
            <geometry>
                <cylinder length="0.0526" radius="0.04"/>
            </geometry>
        </collision>

        <collision name="base_link_collision_camera">
            <origin xyz="0.184025 0 0.072" rpy="0 0 0"/>
            <geometry>
                <box size="0.02805 0.09 0.025"/>
            </geometry>
        </collision>

        <visual name="base_link_main_visual">
            <origin xyz="0 0 0" rpy="1.57 0 0"/>
            <geometry>
                <mesh filename="file://$(find neobot)/meshes/base_link_main.STL" scale="1 1 1"/>
            </geometry>
            <material name="aluminium"/>
        </visual>
        <visual name="base_link_lidar_visual">
            <origin xyz="0 0 0" rpy="1.57 0 0"/>
            <geometry>
                <mesh filename="file://$(find neobot)/meshes/lidar.STL" scale="1 1 1"/>
            </geometry>
            <material name="dark_grey"/>
        </visual>
        <visual name="base_link_realsense_visual">
            <origin xyz="0 0 0" rpy="1.57 0 0"/>
            <geometry>
                <mesh filename="file://$(find neobot)/meshes/realsense.STL" scale="1 1 1"/>
            </geometry>
            <material name="plastic"/>
        </visual>
        <visual name="base_link_left_motor_visual">
            <origin xyz="0.02 0.15 0" rpy="0 0 3.14"/>
            <geometry>
                <mesh filename="file://$(find neobot)/meshes/motor.STL" scale="1 1 1"/>
            </geometry>
            <material name="yellow"/>
        </visual>
        <visual name="base_link_right_motor_visual">
            <origin xyz="-0.02 -0.15 0" rpy="0 0 0"/>
            <geometry>
                <mesh filename="file://$(find neobot)/meshes/motor.STL" scale="1 1 1"/>
            </geometry>
            <material name="yellow"/>
        </visual>
    </link>

    <joint name="base_footprint_joint" type="fixed">
        <parent link="base_footprint"/>
        <child link="base_link"/>
        <origin xyz="0 0 0.0345" rpy="0 0 0"/>
    </joint>



    <link name="left_wheel_link">
        <inertial>
            <origin xyz="0 0.015369 0" rpy="0 0 0"/>
            <mass value="0.132"/>
            <inertia ixx="0.000103824895" ixy="0" ixz="0"
                    iyy="0.000183869513" iyz="0" izz="0.000103824895"/>
        </inertial>
        <collision name="left_wheel_link_collision">
            <origin xyz="0 0.02 0" rpy="1.57079632679 0 0"/>
            <geometry>
                <cylinder length="0.04" radius="0.05"/>
            </geometry>
            <surface>
                <friction>
                    <ode mu="5.00" mu2="5.00" slip1="0" slip2="0"/>
                </friction>
            </surface>
        </collision>
        <visual name="left_wheel_link_visual">
            <origin xyz="0 0 0" rpy="0 0 0"/>
            <geometry>
                <mesh filename="file://$(find neobot)/meshes/left_wheel_link.STL" scale="1 1 1"/>
            </geometry>
            <material name="red"/>
        </visual>
    </link>

    <joint name="left_wheel_joint" type="continuous">
        <parent link="base_link"/>
        <child link="left_wheel_link"/>
        <origin xyz="0 0.136 0.0155" rpy="0 0 0"/>
        <axis xyz="0 1 0"/>
    </joint>



    <link name="right_wheel_link">
        <inertial>
            <origin xyz="0 -0.015369 0" rpy="0 0 0"/>
            <mass value="0.132"/>
            <inertia ixx="0.000103824895" ixy="0" ixz="0"
                    iyy="0.000183869513" iyz="0" izz="0.000103824895"/>
        </inertial>
        <collision name="right_wheel_link_collision">
            <origin xyz="0 -0.02 0" rpy="1.57079632679 0 0"/>
            <geometry>
                <cylinder length="0.04" radius="0.05"/>
            </geometry>
            <surface>
                <friction>
                    <ode mu="5.00" mu2="5.00" slip1="0" slip2="0"/>
                </friction>
            </surface>
        </collision>
        <visual name="right_wheel_link_visual">
            <origin xyz="0 0 0" rpy="0 0 0"/>
            <geometry>
                <mesh filename="file://$(find neobot)/meshes/right_wheel_link.STL" scale="1 1 1"/>
            </geometry>
            <material name="red"/>
        </visual>
    </link>

    <joint name="right_wheel_joint" type="continuous">
        <parent link="base_link"/>
        <child link="right_wheel_link"/>
        <origin xyz="0 -0.136 0.0155" rpy="0 0 0"/>
        <axis xyz="0 1 0"/>
    </joint>



    <link name="front_castor_link">
        <inertial>
            <origin xyz="0 0 0" rpy="0 0 0"/>
            <mass value="0.0138"/>
            <inertia ixx="0.000000312122139" ixy="0" ixz="0"
                    iyy="0.000000312122139" iyz="0" izz="0.000000312122139"/>
        </inertial>
        <collision name="front_castor_link_collision">
            <origin xyz="0 0 0" rpy="0 0 0"/>
            <geometry>
                <sphere radius="0.0075"/>
            </geometry>
            <surface>
                <friction>
                    <ode mu="0.00" mu2="0.00"/>
                </friction>
            </surface>
        </collision>
        <visual name="front_castor_link_visual">
            <origin xyz="0 0 0" rpy="0 0 0"/>
            <geometry>
                <mesh filename="file://$(find neobot)/meshes/front_castor_link.STL" scale="1 1 1"/>
            </geometry>
            <material name="red"/>
        </visual>
    </link>

    <joint name="front_castor_joint" type="fixed">
        <parent link="base_link"/>
        <child link="front_castor_link"/>
        <origin xyz="0.12 0 -0.0265" rpy="0 0 0"/>
    </joint>



    <link name="rear_castor_link">
        <inertial>
            <origin xyz="0 0 0" rpy="0 0 0"/>
            <mass value="0.0138"/>
            <inertia ixx="0.000000312122139" ixy="0" ixz="0"
                    iyy="0.000000312122139" iyz="0" izz="0.000000312122139"/>
        </inertial>
        <collision name="rear_castor_link_collision">
            <origin xyz="0 0 0" rpy="0 0 0"/>
            <geometry>
                <sphere radius="0.0075"/>
            </geometry>
            <surface>
                <friction>
                    <ode mu="0.00" mu2="0.00"/>
                </friction>
            </surface>
        </collision>
        <visual name="rear_castor_link_visual">
            <origin xyz="0 0 0" rpy="0 0 0"/>
            <geometry>
                <mesh filename="file://$(find neobot)/meshes/rear_castor_link.STL" scale="1 1 1"/>
            </geometry>
            <material name="red"/>
        </visual>
    </link>

    <joint name="rear_castor_joint" type="fixed">
        <parent link="base_link"/>
        <child link="rear_castor_link"/>
        <origin xyz="-0.12 0 -0.0265" rpy="0 0 0"/>
    </joint>



    <xacro:if value="$(arg use_imu)">
        <link name="imu_link"/>

        <joint name="imu_joint" type="fixed">
            <parent link="base_link"/>
            <child link="imu_link"/>
            <origin xyz="0 0 0" rpy="0 0 0"/>
        </joint>
    </xacro:if>


    <xacro:if value="$(arg use_lidar)">
        <link name="lidar_link"/>

        <joint name="lidar_joint" type="fixed">
            <parent link="base_link"/>
            <child link="lidar_link"/>
            <origin xyz="0.18 0 0.0376" rpy="0 0 0"/>
        </joint>
    </xacro:if>


    <xacro:if value="$(arg use_camera)">
        <link name="camera_link"/>

        <joint name="camera_joint" type="fixed">
            <parent link="base_link"/>
            <child link="camera_link"/>
            <origin xyz="0.19905 0 0.072" rpy="0 0 0"/>
        </joint>
    </xacro:if>


</robot>
